Workbook

Sheet Explanation
A1: Dispute lawyers: This is interesting (pun-intended)
A2: Judicial interest paragraphs often look simple (“2.5% per annum from [date] until [date]”), but courts quietly make different assumptions about how to turn dates into “years” in calculating interest.
A3: In some cases, the calculation uses a type of Day Count Convention known as “Actual/365 Fixed” (actual number of days ÷ 365); in others, it uses an “Anniversary/365” style (whole calendar years counted as integers, with only leftover days ÷ 365). A third approach, Actual/Actual, weights each day by whether it falls in a leap year. These choices affect leap years, stub periods, and ultimately the total interest.
A5: Example A – Waddington Ltd v Chan Chun Hoo Thomas (HCA 3291/2003)
A6: The court stated that the 1st Defendant must pay “simple interest at 2.5% per annum on the judgment sum of HK$33,511,220.32 from 28 September 2000 until the date of judgment”, and later noted that the 1st Defendant paid “the sum of HK$44,597,466.49 (comprising the Judgment Sum and pre‑judgment interest thereon at 2.5% per annum) into court”. The interest component is HK$44,597,466.49 − HK$33,511,220.32 = HK$11,086,246.17.
A7: In this tool, that figure is reproduced by assuming that every calendar day between the start and end dates that we choose to “include” contributes 1/365 of a year (Actual/365 Fixed). The period from 28 September 2000 to 18 December 2013 contains 4,830 interest days, derived as: 13 years × 365 + 3 leap‑year days (2004, 2008, 2012) + 2 (Sep) + 31 (Oct) + 30 (Nov) + 18 (Dec) + 1 (included start day bearing interest) = 4,830 days. The pre‑judgment interest then follows directly from the formula: HK$33,511,220.32 × 2.5% ÷ 365 × 4,830.00 = HK$11,086,246.17, matching the judgment.
A8: Example B – Easy Policy Finance Ltd v 陳海濱 (HCA 1256/2021, [2025] HKCFI 4295)
A9: The court set out the interest as follows: • “Interest from 21 August 2015 to 20 August 2021 at 24% p.a.: HK$10,765,000 × 24% × 6 years = HK$15,501,600.00.” • “Interest from 21 August 2021 to the date of this judgment (22 September 2025) at 24% p.a.: HK$10,765,000 × 24% × (133/365 days + 3 years + 265/365 days) = HK$10,567,985.75.”
A10: These expressions show that the court is effectively using an “Anniversary/365” convention: – Full calendar years are counted as whole numbers (6 years; then 3 years), and – Only the “stub” periods at the start and end are converted to days ÷ 365 (133/365 and 265/365). In this tool, that behaviour is captured by setting Day Count Convention = Anniversary/365 and choosing inclusive start/end flags so that the total year fraction equals 6 for the first period and 133/365 + 3 + 265/365 for the second.
A11: The judgment also refers to a “daily interest of HK$7,078.36” in the first period. That daily amount equals HK$10,765,000 × 24% ÷ 365, which assumes every year has 365 days. However, if we multiplied that daily interest by the actual number of days between 21 August 2015 and 20 August 2021 (including leap days, using “Actual/365 Fixed”), we would use 2,192 interest days, derived as: 6 × 365 days + 2 leap‑year days - 1 day (from 21 Aug to 20 Aug) + 1 (included start day bearing interest) = 2,192 days HK$7,078.36 × 2,192 ≈ HK$15,515,756.71 does not match the court’s HK$15,501,600.00 figure. The court’s number is only recovered if we treat the period as exactly 6 years of 365 days (ignoring leap days): HK$7,078.36 × 365 × 6 ≈ HK$15,501,600.00. This is precisely what the Anniversary/365 option in the Day Count Convention setting is intended to reflect.
A13: Let's give it a go!
A14: This tool makes those hidden assumptions explicit. You choose a Day Count Convention (Actual/365 Fixed, Anniversary/365, Actual/Actual) and set, for each period, whether the start and end days are included. The spreadsheet then computes a year fraction consistent with those choices and shows you, step‑by‑step, how the interest follows from the judgment’s wording.
... A20: The Explanation sheet (this page) converts the calculations into plain‑language statements for a clear understanding of the calculations.
A22: Short summary: | B22: Key settings summary (interpretation choices) :
B23: ="Day Count Convention: " & Input!C4 -> Day Count Convention: Actual/365 Fixed
A24: ="Total interest from " & TEXT(MIN(Calculation!B2:B1025),"dd mmm yyyy") & " to " & TEXT(MAX(Calculation!C2:C1025),"dd mmm yyyy") & " is HK$" & TEXT(SUM(Calculation!O2:O1025),"#,##0.00") & ", giving a total amount of HK$" & TEXT(MAX(Calculation!P2:P1025),"#,##0.00") & "." -> Total interest from 21 Aug 2015 to 22 Sep 2025 is HK$13,807,513.42, giving a total amount of HK$24,572,513.42. | B24: {=IF( Calculation!A2:A1025="", , "Period " & Calculation!A2:A1025 & " – Include Start: " & IF( INDEX(Input!$K$7:$K1025, Calculation!A2:A1025), "Yes", "No" ) & ", Include End: " & IF( INDEX(Input!$L$7:$L1025, Calculation!A2:A1025), "Yes", "No" ) )} -> Period 1 – Include Start: Yes, Include End: Yes
A25: Interest breakdown: | B25: Period 2 – Include Start: No, Include End: Yes
A26: {=IF( Calculation!A2:A1025="", , "Period " & Calculation!A2:A1025 & ": interest from " & TEXT(Calculation!B2:B1025,"dd mmm yyyy") & " to " & TEXT(Calculation!C2:C1025,"dd mmm yyyy") & " at " & TEXT(Calculation!G2:G1025,"0.00%") & " " & Lower(Calculation!F2:F1025) & " on the " & LOWER(Calculation!K2:K1025) & IF( Calculation!E2:E1025="Simple", ": HK$" & TEXT( IF( Calculation!K2:K1025="Initial Principal", Input!$C$2, Calculation!N2:N1025 ), "#,##0.00" ) & " × " & TEXT(Calculation!L2:L1025,"0.00%") & " × " & TEXT(Calculation!R2:R1025,"0.0000") & " years = HK$" & TEXT(Calculation!O2:O1025,"#,##0.00"), ", compounded " & SWITCH( Calculation!H2:H1025, "Monthly","monthly", "Quarterly","quarterly", "Semi-annual","semi-annually", "Annual","annually", LOWER(Calculation!H2:H1025) ) & ": HK$" & TEXT( IF( Calculation!K2:K1025="Initial Principal", Input!$C$2, Calculation!N2:N1025 ), "#,##0.00" ) & " × ((1 + " & TEXT(Calculation!L2:L1025,"0.00%") & "/" & SWITCH( Calculation!H2:H1025, "Monthly",12, "Quarterly",4, "Semi-annual",2, "Annual",1, 1 ) & ")^(" & SWITCH( Calculation!H2:H1025, "Monthly",12, "Quarterly",4, "Semi-annual",2, "Annual",1, 1 ) & "×" & TEXT(Calculation!R2:R1025,"0.0000") & ") - 1) = HK$" & TEXT(Calculation!O2:O1025,"#,##0.00") ) & ". This period has " & Calculation!D2:D1025 & " interest days" & IF( INDEX(Input!$K$7:$K1025,Calculation!A2:A1025), IF( INDEX(Input!$L$7:$L1025,Calculation!A2:A1025), " (including both the start day and the end day)", " (including the start day and excluding the end day)" ), IF( INDEX(Input!$L$7:$L1025,Calculation!A2:A1025), " (including the end day and excluding the start day)", " (excluding both the start day and the end day)" ) ) & ", which is " & TEXT(Calculation!R2:R1025,"0.0000") & " year(s), derived as: " & IF( Input!$C$4="Actual/365 Fixed", TEXT(Calculation!R2:R1025,"0.0000") & " year(s) = " & Calculation!D2:D1025 & " interest days ÷ 365.", IF( Input!$C$4="Anniversary/365", TEXT(Calculation!R2:R1025,"0.0000") & " year(s) = " & IF(Calculation!T2:T1025<>"",Calculation!T2:T1025 & " whole year(s) + ","") & Calculation!U2:U1025 & " day(s) ÷ 365.", IF( Input!$C$4="Actual/Actual", TEXT(Calculation!R2:R1025,"0.0000") & " year(s) = " & Calculation!V2:V1025 & " day(s) ÷ 365 + " & Calculation!W2:W1025 & " day(s) ÷ 366.", TEXT(Calculation!R2:R1025,"0.0000") & " year(s) following the selected convention." ) ) ) )} -> Period 1: interest from 21 Aug 2015 to 20 Aug 2021 at 5.00% per annum on the initial principal: HK$10,765,000.00 × 5.00% × 6.0055 years = HK$3,232,449.32. This period has 2192 interest days (including both the start day and the end day), which is 6.0055 year(s), derived as: 6.0055 year(s) = 2192 interest days ÷ 365.
A27: Period 2: interest from 20 Aug 2021 to 22 Sep 2025 at 24.00% per annum on the initial principal: HK$10,765,000.00 × 24.00% × 4.0932 years = HK$10,575,064.11. This period has 1494 interest days (including the end day and excluding the start day), which is 4.0932 year(s), derived as: 4.0932 year(s) = 1494 interest days ÷ 365.

Sheet Input
A1: Initial information
B2: Initial Principal | C2: 10765000
B3: Start Date | C3: 42237
B4: Day Count Convention | C4: Actual/365 Fixed
A5: Period table
A6: Period ID | B6: Start Date | C6: End Date | D6: Interest Type | E6: Interest Basis | F6: Nominal Rate | G6: Rate Basis | H6: Compounding Freq. | I6: Adjust. to Start Sum | J6: Adjust. to End Sum | K6: Include Start Day | L6: Include End Day
A7: =IF($C7="","",IF(ROW()=7,1,A6+1)) -> 1 | B7: =IF($C7="","",IF(ROW()=7,Input!$C$3,C6)) -> 42237 | C7: 44428 | D7: Simple | E7: Initial Principal | F7: 0.05 | G7: Per annum | H7: Annual | I7: 0 | J7: 0 | K7: TRUE | L7: TRUE
A8: =IF($C8="","",IF(ROW()=7,1,A7+1)) -> 2 | B8: =IF($C8="","",IF(ROW()=7,Input!$C$3,C7)) -> 44428 | C8: 45922 | D8: Simple | E8: Initial Principal | F8: 0.24 | G8: Per annum | H8: Annual | I8: 0 | J8: 0 | K8: FALSE | L8: TRUE
A9: =IF($C9="","",IF(ROW()=7,1,A8+1)) | B9: =IF($C9="","",IF(ROW()=7,Input!$C$3,C8)) | I9: 0 | J9: 0 | K9: FALSE | L9: TRUE
A10: =IF($C10="","",IF(ROW()=7,1,A9+1)) | B10: =IF($C10="","",IF(ROW()=7,Input!$C$3,C9)) | I10: 0 | J10: 0 | K10: FALSE | L10: TRUE
A11: =IF($C11="","",IF(ROW()=7,1,A10+1)) | B11: =IF($C11="","",IF(ROW()=7,Input!$C$3,C10)) | I11: 0 | J11: 0 | K11: FALSE | L11: TRUE
A12: =IF($C12="","",IF(ROW()=7,1,A11+1)) | B12: =IF($C12="","",IF(ROW()=7,Input!$C$3,C11)) | I12: 0 | J12: 0 | K12: FALSE | L12: TRUE
A13: =IF($C13="","",IF(ROW()=7,1,A12+1)) | B13: =IF($C13="","",IF(ROW()=7,Input!$C$3,C12)) | I13: 0 | J13: 0 | K13: FALSE | L13: TRUE
A14: =IF($C14="","",IF(ROW()=7,1,A13+1)) | B14: =IF($C14="","",IF(ROW()=7,Input!$C$3,C13)) | I14: 0 | J14: 0 | K14: FALSE | L14: TRUE
A15: =IF($C15="","",IF(ROW()=7,1,A14+1)) | B15: =IF($C15="","",IF(ROW()=7,Input!$C$3,C14)) | I15: 0 | J15: 0 | K15: FALSE | L15: TRUE
A16: =IF($C16="","",IF(ROW()=7,1,A15+1)) | B16: =IF($C16="","",IF(ROW()=7,Input!$C$3,C15)) | I16: 0 | J16: 0 | K16: FALSE | L16: TRUE
A17: =IF($C17="","",IF(ROW()=7,1,A16+1)) | B17: =IF($C17="","",IF(ROW()=7,Input!$C$3,C16)) | I17: 0 | J17: 0 | K17: FALSE | L17: TRUE
A18: =IF($C18="","",IF(ROW()=7,1,A17+1)) | B18: =IF($C18="","",IF(ROW()=7,Input!$C$3,C17)) | I18: 0 | J18: 0 | K18: FALSE | L18: TRUE
A19: =IF($C19="","",IF(ROW()=7,1,A18+1)) | B19: =IF($C19="","",IF(ROW()=7,Input!$C$3,C18)) | I19: 0 | J19: 0 | K19: FALSE | L19: TRUE
A20: =IF($C20="","",IF(ROW()=7,1,A19+1)) | B20: =IF($C20="","",IF(ROW()=7,Input!$C$3,C19)) | I20: 0 | J20: 0 | K20: FALSE | L20: TRUE
... A1008: =IF($C1008="","",IF(ROW()=7,1,A1007+1)) | B1008: =IF($C1008="","",IF(ROW()=7,Input!$C$3,C1007)) | I1008: 0 | J1008: 0 | K1008: FALSE | L1008: TRUE

Sheet Visualisation

Sheet Calculation
A1: Period ID | B1: Start | C1: End | D1: Days | E1: Type | F1: Basis | G1: Nominal Rate | H1: Comp Freq | I1: Start Contrib | J1: End Contrib | K1: Interest Basis | L1: Annualised Nominal Rate | M1: Effective Period Rate | N1: Principal Start | O1: Interest | P1: Principal End | Q1: Cumulative Interest | R1: Year Fraction | S1: Effective Annual Rate | T1: Whole Years (Anniv) | U1: Stub Days (Anniv)
A2: {=IF(Input!A7:A1503="",,Input!A7:A1503)} -> 1 | B2: {=IF(Input!B7:B1503="",,Input!B7:B1503)} -> 42237 | C2: {=IF(Input!C7:C1503="",,Input!C7:C1503)} -> 44428 | D2: {=IF(B2:B1503="",, (C2:C1503 - B2:B1503) + IF(Input!K7:K1503,1,0) + IF(Input!L7:L1503,1,0) - 1 )} -> 2192 | E2: {=IF(Input!D7:D1503="",,Input!D7:D1503)} -> Simple | F2: {=IF(Input!G7:G1503="",,Input!G7:G1503)} -> Per annum | G2: {=IF(Input!F7:F1503="",,Input!F7:F1503)} -> 0.05 | H2: {=IF(Input!H7:H1503="",,Input!H7:H1503)} -> Annual | I2: {=IF(Input!I7:I1503="",,Input!I7:I1503)} -> 0 | J2: {=IF(Input!J7:J1503="",,Input!J7:J1503)} -> 0 | K2: {=IF(Input!E7:E1503="",,Input!E7:E1503)} -> Initial Principal | L2: {=IF(E2:E1503="", , SWITCH(F2:F1503, "Per annum", G2:G1503, "Per month", G2:G1503*12, "Per quarter",G2:G1503*4, "Per day", G2:G1503*365, G2:G1503 ) )} -> 0.05 | M2: =IF( E2="", , IF( E2="Simple", L2 * R2, LET( t, R2, m, SWITCH(H2,"Monthly",12,"Quarterly",4,"Semi-annual",2,"Annual",1,1), (1 + L2/m)^(m*t) - 1 ) ) ) -> 0.30027397 | N2: =IF(A2="",,IF(ROW()=2, Input!$C$2 + I2, P1 + I2)) -> 10765000 | O2: =IF(A2="",, IF(K2="Initial principal", Input!$C$2 * M2, N2 * M2 ) ) -> 3232449.3 | P2: =IF(A2="",,N2 + O2 + J2) -> 13997449 | Q2: =IF(A2="",,IF(ROW()=2,O2,Q1+O2)) -> 3232449.3 | R2: {=IF( B2="", , SWITCH( Input!$C$4, "Actual/365 Fixed", YEARFRAC( B2 + IF(INDEX(Input!$K$7:$K1503,ROW()-1),0,1), C2 + IF(INDEX(Input!$L$7:$L1503,ROW()-1),1,0), 3 ), "Anniversary/365", DATEDIF( B2 + IF(INDEX(Input!$K$7:$K1503,ROW()-1),0,1), C2 + IF(INDEX(Input!$L$7:$L1503,ROW()-1),1,0), "Y" ) + ( (C2 + IF(INDEX(Input!$L$7:$L1503,ROW()-1),1,0)) - EDATE( B2 + IF(INDEX(Input!$K$7:$K1503,ROW()-1),0,1), 12*DATEDIF( B2 + IF(INDEX(Input!$K$7:$K1503,ROW()-1),0,1), C2 + IF(INDEX(Input!$L$7:$L1503,ROW()-1),1,0), "Y" ) ) ) / 365, "Actual/Actual", YEARFRAC( B2 + IF(INDEX(Input!$K$7:$K1503,ROW()-1),0,1), C2 + IF(INDEX(Input!$L$7:$L1503,ROW()-1),1,0), 1 ), YEARFRAC( B2 + IF(INDEX(Input!$K$7:$K1503,ROW()-1),0,1), C2 + IF(INDEX(Input!$L$7:$L1503,ROW()-1),1,0), 3 ) ) )} -> 6.0054795 | S2: =IF( E2="", , IF( E2="Simple", L2, (1 + L2 / SWITCH(H2,"Monthly",12,"Quarterly",4,"Semi-annual",2,"Annual",1,1)) ^ SWITCH(H2,"Monthly",12,"Quarterly",4,"Semi-annual",2,"Annual",1,1) - 1 ) ) -> 0.05 | T2: {=IF( B2="", , DATEDIF( B2 + IF(INDEX(Input!$K$7:$K1503,ROW()-1),0,1), C2 + IF(INDEX(Input!$L$7:$L1503,ROW()-1),1,0), "Y" ) )} -> 6 | U2: {=IF( B2="", , (C2 + IF(INDEX(Input!$L$7:$L1503,ROW()-1),1,0)) - EDATE( B2 + IF(INDEX(Input!$K$7:$K1503,ROW()-1),0,1), 12*T2 ) )} -> 0 | V2: =IF( D2="", , R2*365*366 - 365*D2 ) -> 2192 | W2: =IF( D2="", , D2 - V2 ) -> 0
A3: 2 | B3: 44428 | C3: 45922 | D3: 1494 | E3: Simple | F3: Per annum | G3: 0.24 | H3: Annual | I3: 0 | J3: 0 | K3: Initial Principal | L3: 0.24 | M3: =IF( E3="", , IF( E3="Simple", L3 * R3, LET( t, R3, m, SWITCH(H3,"Monthly",12,"Quarterly",4,"Semi-annual",2,"Annual",1,1), (1 + L3/m)^(m*t) - 1 ) ) ) -> 0.98235616 | N3: =IF(A3="",,IF(ROW()=2, Input!$C$2 + I3, P2 + I3)) -> 13997449 | O3: =IF(A3="",, IF(K3="Initial principal", Input!$C$2 * M3, N3 * M3 ) ) -> 10575064 | P3: =IF(A3="",,N3 + O3 + J3) -> 24572513 | Q3: =IF(A3="",,IF(ROW()=2,O3,Q2+O3)) -> 13807513 | R3: {=IF( B3="", , SWITCH( Input!$C$4, "Actual/365 Fixed", YEARFRAC( B3 + IF(INDEX(Input!$K$7:$K1503,ROW()-1),0,1), C3 + IF(INDEX(Input!$L$7:$L1503,ROW()-1),1,0), 3 ), "Anniversary/365", DATEDIF( B3 + IF(INDEX(Input!$K$7:$K1503,ROW()-1),0,1), C3 + IF(INDEX(Input!$L$7:$L1503,ROW()-1),1,0), "Y" ) + ( (C3 + IF(INDEX(Input!$L$7:$L1503,ROW()-1),1,0)) - EDATE( B3 + IF(INDEX(Input!$K$7:$K1503,ROW()-1),0,1), 12*DATEDIF( B3 + IF(INDEX(Input!$K$7:$K1503,ROW()-1),0,1), C3 + IF(INDEX(Input!$L$7:$L1503,ROW()-1),1,0), "Y" ) ) ) / 365, "Actual/Actual", YEARFRAC( B3 + IF(INDEX(Input!$K$7:$K1503,ROW()-1),0,1), C3 + IF(INDEX(Input!$L$7:$L1503,ROW()-1),1,0), 1 ), YEARFRAC( B3 + IF(INDEX(Input!$K$7:$K1503,ROW()-1),0,1), C3 + IF(INDEX(Input!$L$7:$L1503,ROW()-1),1,0), 3 ) ) )} -> 4.0931507 | S3: =IF( E3="", , IF( E3="Simple", L3, (1 + L3 / SWITCH(H3,"Monthly",12,"Quarterly",4,"Semi-annual",2,"Annual",1,1)) ^ SWITCH(H3,"Monthly",12,"Quarterly",4,"Semi-annual",2,"Annual",1,1) - 1 ) ) -> 0.24 | T3: {=IF( B3="", , DATEDIF( B3 + IF(INDEX(Input!$K$7:$K1503,ROW()-1),0,1), C3 + IF(INDEX(Input!$L$7:$L1503,ROW()-1),1,0), "Y" ) )} -> 4 | U3: {=IF( B3="", , (C3 + IF(INDEX(Input!$L$7:$L1503,ROW()-1),1,0)) - EDATE( B3 + IF(INDEX(Input!$K$7:$K1503,ROW()-1),0,1), 12*T3 ) )} -> 33 | V3: =IF( D3="", , R3*365*366 - 365*D3 ) -> 1494 | W3: =IF( D3="", , D3 - V3 ) -> 0
I4: 0 | J4: 0 | M4: =IF( E4="", , IF( E4="Simple", L4 * R4, LET( t, R4, m, SWITCH(H4,"Monthly",12,"Quarterly",4,"Semi-annual",2,"Annual",1,1), (1 + L4/m)^(m*t) - 1 ) ) ) | N4: =IF(A4="",,IF(ROW()=2, Input!$C$2 + I4, P3 + I4)) | O4: =IF(A4="",, IF(K4="Initial principal", Input!$C$2 * M4, N4 * M4 ) ) | P4: =IF(A4="",,N4 + O4 + J4) | Q4: =IF(A4="",,IF(ROW()=2,O4,Q3+O4)) | R4: {=IF( B4="", , SWITCH( Input!$C$4, "Actual/365 Fixed", YEARFRAC( B4 + IF(INDEX(Input!$K$7:$K1503,ROW()-1),0,1), C4 + IF(INDEX(Input!$L$7:$L1503,ROW()-1),1,0), 3 ), "Anniversary/365", DATEDIF( B4 + IF(INDEX(Input!$K$7:$K1503,ROW()-1),0,1), C4 + IF(INDEX(Input!$L$7:$L1503,ROW()-1),1,0), "Y" ) + ( (C4 + IF(INDEX(Input!$L$7:$L1503,ROW()-1),1,0)) - EDATE( B4 + IF(INDEX(Input!$K$7:$K1503,ROW()-1),0,1), 12*DATEDIF( B4 + IF(INDEX(Input!$K$7:$K1503,ROW()-1),0,1), C4 + IF(INDEX(Input!$L$7:$L1503,ROW()-1),1,0), "Y" ) ) ) / 365, "Actual/Actual", YEARFRAC( B4 + IF(INDEX(Input!$K$7:$K1503,ROW()-1),0,1), C4 + IF(INDEX(Input!$L$7:$L1503,ROW()-1),1,0), 1 ), YEARFRAC( B4 + IF(INDEX(Input!$K$7:$K1503,ROW()-1),0,1), C4 + IF(INDEX(Input!$L$7:$L1503,ROW()-1),1,0), 3 ) ) )} | S4: =IF( E4="", , IF( E4="Simple", L4, (1 + L4 / SWITCH(H4,"Monthly",12,"Quarterly",4,"Semi-annual",2,"Annual",1,1)) ^ SWITCH(H4,"Monthly",12,"Quarterly",4,"Semi-annual",2,"Annual",1,1) - 1 ) ) | T4: {=IF( B4="", , DATEDIF( B4 + IF(INDEX(Input!$K$7:$K1503,ROW()-1),0,1), C4 + IF(INDEX(Input!$L$7:$L1503,ROW()-1),1,0), "Y" ) )} | U4: {=IF( B4="", , (C4 + IF(INDEX(Input!$L$7:$L1503,ROW()-1),1,0)) - EDATE( B4 + IF(INDEX(Input!$K$7:$K1503,ROW()-1),0,1), 12*S4 ) )} | V4: =IF( D4="", , R4*365*366 - 365*D4 ) | W4: =IF( D4="", , D4 - V4 )
I5: 0 | J5: 0 | M5: =IF( E5="", , IF( E5="Simple", L5 * R5, LET( t, R5, m, SWITCH(H5,"Monthly",12,"Quarterly",4,"Semi-annual",2,"Annual",1,1), (1 + L5/m)^(m*t) - 1 ) ) ) | N5: =IF(A5="",,IF(ROW()=2, Input!$C$2 + I5, P4 + I5)) | O5: =IF(A5="",, IF(K5="Initial principal", Input!$C$2 * M5, N5 * M5 ) ) | P5: =IF(A5="",,N5 + O5 + J5) | Q5: =IF(A5="",,IF(ROW()=2,O5,Q4+O5)) | R5: {=IF( B5="", , SWITCH( Input!$C$4, "Actual/365 Fixed", YEARFRAC( B5 + IF(INDEX(Input!$K$7:$K1503,ROW()-1),0,1), C5 + IF(INDEX(Input!$L$7:$L1503,ROW()-1),1,0), 3 ), "Anniversary/365", DATEDIF( B5 + IF(INDEX(Input!$K$7:$K1503,ROW()-1),0,1), C5 + IF(INDEX(Input!$L$7:$L1503,ROW()-1),1,0), "Y" ) + ( (C5 + IF(INDEX(Input!$L$7:$L1503,ROW()-1),1,0)) - EDATE( B5 + IF(INDEX(Input!$K$7:$K1503,ROW()-1),0,1), 12*DATEDIF( B5 + IF(INDEX(Input!$K$7:$K1503,ROW()-1),0,1), C5 + IF(INDEX(Input!$L$7:$L1503,ROW()-1),1,0), "Y" ) ) ) / 365, "Actual/Actual", YEARFRAC( B5 + IF(INDEX(Input!$K$7:$K1503,ROW()-1),0,1), C5 + IF(INDEX(Input!$L$7:$L1503,ROW()-1),1,0), 1 ), YEARFRAC( B5 + IF(INDEX(Input!$K$7:$K1503,ROW()-1),0,1), C5 + IF(INDEX(Input!$L$7:$L1503,ROW()-1),1,0), 3 ) ) )} | S5: =IF( E5="", , IF( E5="Simple", L5, (1 + L5 / SWITCH(H5,"Monthly",12,"Quarterly",4,"Semi-annual",2,"Annual",1,1)) ^ SWITCH(H5,"Monthly",12,"Quarterly",4,"Semi-annual",2,"Annual",1,1) - 1 ) ) | T5: {=IF( B5="", , DATEDIF( B5 + IF(INDEX(Input!$K$7:$K1503,ROW()-1),0,1), C5 + IF(INDEX(Input!$L$7:$L1503,ROW()-1),1,0), "Y" ) )} | U5: {=IF( B5="", , (C5 + IF(INDEX(Input!$L$7:$L1503,ROW()-1),1,0)) - EDATE( B5 + IF(INDEX(Input!$K$7:$K1503,ROW()-1),0,1), 12*S5 ) )} | V5: =IF( D5="", , R5*365*366 - 365*D5 ) | W5: =IF( D5="", , D5 - V5 )
I6: 0 | J6: 0 | M6: =IF( E6="", , IF( E6="Simple", L6 * R6, LET( t, R6, m, SWITCH(H6,"Monthly",12,"Quarterly",4,"Semi-annual",2,"Annual",1,1), (1 + L6/m)^(m*t) - 1 ) ) ) | N6: =IF(A6="",,IF(ROW()=2, Input!$C$2 + I6, P5 + I6)) | O6: =IF(A6="",, IF(K6="Initial principal", Input!$C$2 * M6, N6 * M6 ) ) | P6: =IF(A6="",,N6 + O6 + J6) | Q6: =IF(A6="",,IF(ROW()=2,O6,Q5+O6)) | R6: {=IF( B6="", , SWITCH( Input!$C$4, "Actual/365 Fixed", YEARFRAC( B6 + IF(INDEX(Input!$K$7:$K1503,ROW()-1),0,1), C6 + IF(INDEX(Input!$L$7:$L1503,ROW()-1),1,0), 3 ), "Anniversary/365", DATEDIF( B6 + IF(INDEX(Input!$K$7:$K1503,ROW()-1),0,1), C6 + IF(INDEX(Input!$L$7:$L1503,ROW()-1),1,0), "Y" ) + ( (C6 + IF(INDEX(Input!$L$7:$L1503,ROW()-1),1,0)) - EDATE( B6 + IF(INDEX(Input!$K$7:$K1503,ROW()-1),0,1), 12*DATEDIF( B6 + IF(INDEX(Input!$K$7:$K1503,ROW()-1),0,1), C6 + IF(INDEX(Input!$L$7:$L1503,ROW()-1),1,0), "Y" ) ) ) / 365, "Actual/Actual", YEARFRAC( B6 + IF(INDEX(Input!$K$7:$K1503,ROW()-1),0,1), C6 + IF(INDEX(Input!$L$7:$L1503,ROW()-1),1,0), 1 ), YEARFRAC( B6 + IF(INDEX(Input!$K$7:$K1503,ROW()-1),0,1), C6 + IF(INDEX(Input!$L$7:$L1503,ROW()-1),1,0), 3 ) ) )} | S6: =IF( E6="", , IF( E6="Simple", L6, (1 + L6 / SWITCH(H6,"Monthly",12,"Quarterly",4,"Semi-annual",2,"Annual",1,1)) ^ SWITCH(H6,"Monthly",12,"Quarterly",4,"Semi-annual",2,"Annual",1,1) - 1 ) ) | T6: {=IF( B6="", , DATEDIF( B6 + IF(INDEX(Input!$K$7:$K1503,ROW()-1),0,1), C6 + IF(INDEX(Input!$L$7:$L1503,ROW()-1),1,0), "Y" ) )} | U6: {=IF( B6="", , (C6 + IF(INDEX(Input!$L$7:$L1503,ROW()-1),1,0)) - EDATE( B6 + IF(INDEX(Input!$K$7:$K1503,ROW()-1),0,1), 12*S6 ) )} | V6: =IF( D6="", , R6*365*366 - 365*D6 ) | W6: =IF( D6="", , D6 - V6 )
I7: 0 | J7: 0 | M7: =IF( E7="", , IF( E7="Simple", L7 * R7, LET( t, R7, m, SWITCH(H7,"Monthly",12,"Quarterly",4,"Semi-annual",2,"Annual",1,1), (1 + L7/m)^(m*t) - 1 ) ) ) | N7: =IF(A7="",,IF(ROW()=2, Input!$C$2 + I7, P6 + I7)) | O7: =IF(A7="",, IF(K7="Initial principal", Input!$C$2 * M7, N7 * M7 ) ) | P7: =IF(A7="",,N7 + O7 + J7) | Q7: =IF(A7="",,IF(ROW()=2,O7,Q6+O7)) | R7: {=IF( B7="", , SWITCH( Input!$C$4, "Actual/365 Fixed", YEARFRAC( B7 + IF(INDEX(Input!$K$7:$K1503,ROW()-1),0,1), C7 + IF(INDEX(Input!$L$7:$L1503,ROW()-1),1,0), 3 ), "Anniversary/365", DATEDIF( B7 + IF(INDEX(Input!$K$7:$K1503,ROW()-1),0,1), C7 + IF(INDEX(Input!$L$7:$L1503,ROW()-1),1,0), "Y" ) + ( (C7 + IF(INDEX(Input!$L$7:$L1503,ROW()-1),1,0)) - EDATE( B7 + IF(INDEX(Input!$K$7:$K1503,ROW()-1),0,1), 12*DATEDIF( B7 + IF(INDEX(Input!$K$7:$K1503,ROW()-1),0,1), C7 + IF(INDEX(Input!$L$7:$L1503,ROW()-1),1,0), "Y" ) ) ) / 365, "Actual/Actual", YEARFRAC( B7 + IF(INDEX(Input!$K$7:$K1503,ROW()-1),0,1), C7 + IF(INDEX(Input!$L$7:$L1503,ROW()-1),1,0), 1 ), YEARFRAC( B7 + IF(INDEX(Input!$K$7:$K1503,ROW()-1),0,1), C7 + IF(INDEX(Input!$L$7:$L1503,ROW()-1),1,0), 3 ) ) )} | S7: =IF( E7="", , IF( E7="Simple", L7, (1 + L7 / SWITCH(H7,"Monthly",12,"Quarterly",4,"Semi-annual",2,"Annual",1,1)) ^ SWITCH(H7,"Monthly",12,"Quarterly",4,"Semi-annual",2,"Annual",1,1) - 1 ) ) | T7: {=IF( B7="", , DATEDIF( B7 + IF(INDEX(Input!$K$7:$K1503,ROW()-1),0,1), C7 + IF(INDEX(Input!$L$7:$L1503,ROW()-1),1,0), "Y" ) )} | U7: {=IF( B7="", , (C7 + IF(INDEX(Input!$L$7:$L1503,ROW()-1),1,0)) - EDATE( B7 + IF(INDEX(Input!$K$7:$K1503,ROW()-1),0,1), 12*S7 ) )} | V7: =IF( D7="", , R7*365*366 - 365*D7 ) | W7: =IF( D7="", , D7 - V7 )
I8: 0 | J8: 0 | M8: =IF( E8="", , IF( E8="Simple", L8 * R8, LET( t, R8, m, SWITCH(H8,"Monthly",12,"Quarterly",4,"Semi-annual",2,"Annual",1,1), (1 + L8/m)^(m*t) - 1 ) ) ) | N8: =IF(A8="",,IF(ROW()=2, Input!$C$2 + I8, P7 + I8)) | O8: =IF(A8="",, IF(K8="Initial principal", Input!$C$2 * M8, N8 * M8 ) ) | P8: =IF(A8="",,N8 + O8 + J8) | Q8: =IF(A8="",,IF(ROW()=2,O8,Q7+O8)) | R8: {=IF( B8="", , SWITCH( Input!$C$4, "Actual/365 Fixed", YEARFRAC( B8 + IF(INDEX(Input!$K$7:$K1503,ROW()-1),0,1), C8 + IF(INDEX(Input!$L$7:$L1503,ROW()-1),1,0), 3 ), "Anniversary/365", DATEDIF( B8 + IF(INDEX(Input!$K$7:$K1503,ROW()-1),0,1), C8 + IF(INDEX(Input!$L$7:$L1503,ROW()-1),1,0), "Y" ) + ( (C8 + IF(INDEX(Input!$L$7:$L1503,ROW()-1),1,0)) - EDATE( B8 + IF(INDEX(Input!$K$7:$K1503,ROW()-1),0,1), 12*DATEDIF( B8 + IF(INDEX(Input!$K$7:$K1503,ROW()-1),0,1), C8 + IF(INDEX(Input!$L$7:$L1503,ROW()-1),1,0), "Y" ) ) ) / 365, "Actual/Actual", YEARFRAC( B8 + IF(INDEX(Input!$K$7:$K1503,ROW()-1),0,1), C8 + IF(INDEX(Input!$L$7:$L1503,ROW()-1),1,0), 1 ), YEARFRAC( B8 + IF(INDEX(Input!$K$7:$K1503,ROW()-1),0,1), C8 + IF(INDEX(Input!$L$7:$L1503,ROW()-1),1,0), 3 ) ) )} | S8: =IF( E8="", , IF( E8="Simple", L8, (1 + L8 / SWITCH(H8,"Monthly",12,"Quarterly",4,"Semi-annual",2,"Annual",1,1)) ^ SWITCH(H8,"Monthly",12,"Quarterly",4,"Semi-annual",2,"Annual",1,1) - 1 ) ) | T8: {=IF( B8="", , DATEDIF( B8 + IF(INDEX(Input!$K$7:$K1503,ROW()-1),0,1), C8 + IF(INDEX(Input!$L$7:$L1503,ROW()-1),1,0), "Y" ) )} | U8: {=IF( B8="", , (C8 + IF(INDEX(Input!$L$7:$L1503,ROW()-1),1,0)) - EDATE( B8 + IF(INDEX(Input!$K$7:$K1503,ROW()-1),0,1), 12*S8 ) )} | V8: =IF( D8="", , R8*365*366 - 365*D8 ) | W8: =IF( D8="", , D8 - V8 )
I9: 0 | J9: 0 | M9: =IF( E9="", , IF( E9="Simple", L9 * R9, LET( t, R9, m, SWITCH(H9,"Monthly",12,"Quarterly",4,"Semi-annual",2,"Annual",1,1), (1 + L9/m)^(m*t) - 1 ) ) ) | N9: =IF(A9="",,IF(ROW()=2, Input!$C$2 + I9, P8 + I9)) | O9: =IF(A9="",, IF(K9="Initial principal", Input!$C$2 * M9, N9 * M9 ) ) | P9: =IF(A9="",,N9 + O9 + J9) | Q9: =IF(A9="",,IF(ROW()=2,O9,Q8+O9)) | R9: {=IF( B9="", , SWITCH( Input!$C$4, "Actual/365 Fixed", YEARFRAC( B9 + IF(INDEX(Input!$K$7:$K1503,ROW()-1),0,1), C9 + IF(INDEX(Input!$L$7:$L1503,ROW()-1),1,0), 3 ), "Anniversary/365", DATEDIF( B9 + IF(INDEX(Input!$K$7:$K1503,ROW()-1),0,1), C9 + IF(INDEX(Input!$L$7:$L1503,ROW()-1),1,0), "Y" ) + ( (C9 + IF(INDEX(Input!$L$7:$L1503,ROW()-1),1,0)) - EDATE( B9 + IF(INDEX(Input!$K$7:$K1503,ROW()-1),0,1), 12*DATEDIF( B9 + IF(INDEX(Input!$K$7:$K1503,ROW()-1),0,1), C9 + IF(INDEX(Input!$L$7:$L1503,ROW()-1),1,0), "Y" ) ) ) / 365, "Actual/Actual", YEARFRAC( B9 + IF(INDEX(Input!$K$7:$K1503,ROW()-1),0,1), C9 + IF(INDEX(Input!$L$7:$L1503,ROW()-1),1,0), 1 ), YEARFRAC( B9 + IF(INDEX(Input!$K$7:$K1503,ROW()-1),0,1), C9 + IF(INDEX(Input!$L$7:$L1503,ROW()-1),1,0), 3 ) ) )} | S9: =IF( E9="", , IF( E9="Simple", L9, (1 + L9 / SWITCH(H9,"Monthly",12,"Quarterly",4,"Semi-annual",2,"Annual",1,1)) ^ SWITCH(H9,"Monthly",12,"Quarterly",4,"Semi-annual",2,"Annual",1,1) - 1 ) ) | T9: {=IF( B9="", , DATEDIF( B9 + IF(INDEX(Input!$K$7:$K1503,ROW()-1),0,1), C9 + IF(INDEX(Input!$L$7:$L1503,ROW()-1),1,0), "Y" ) )} | U9: {=IF( B9="", , (C9 + IF(INDEX(Input!$L$7:$L1503,ROW()-1),1,0)) - EDATE( B9 + IF(INDEX(Input!$K$7:$K1503,ROW()-1),0,1), 12*S9 ) )} | V9: =IF( D9="", , R9*365*366 - 365*D9 ) | W9: =IF( D9="", , D9 - V9 )
I10: 0 | J10: 0 | M10: =IF( E10="", , IF( E10="Simple", L10 * R10, LET( t, R10, m, SWITCH(H10,"Monthly",12,"Quarterly",4,"Semi-annual",2,"Annual",1,1), (1 + L10/m)^(m*t) - 1 ) ) ) | N10: =IF(A10="",,IF(ROW()=2, Input!$C$2 + I10, P9 + I10)) | O10: =IF(A10="",, IF(K10="Initial principal", Input!$C$2 * M10, N10 * M10 ) ) | P10: =IF(A10="",,N10 + O10 + J10) | Q10: =IF(A10="",,IF(ROW()=2,O10,Q9+O10)) | R10: {=IF( B10="", , SWITCH( Input!$C$4, "Actual/365 Fixed", YEARFRAC( B10 + IF(INDEX(Input!$K$7:$K1503,ROW()-1),0,1), C10 + IF(INDEX(Input!$L$7:$L1503,ROW()-1),1,0), 3 ), "Anniversary/365", DATEDIF( B10 + IF(INDEX(Input!$K$7:$K1503,ROW()-1),0,1), C10 + IF(INDEX(Input!$L$7:$L1503,ROW()-1),1,0), "Y" ) + ( (C10 + IF(INDEX(Input!$L$7:$L1503,ROW()-1),1,0)) - EDATE( B10 + IF(INDEX(Input!$K$7:$K1503,ROW()-1),0,1), 12*DATEDIF( B10 + IF(INDEX(Input!$K$7:$K1503,ROW()-1),0,1), C10 + IF(INDEX(Input!$L$7:$L1503,ROW()-1),1,0), "Y" ) ) ) / 365, "Actual/Actual", YEARFRAC( B10 + IF(INDEX(Input!$K$7:$K1503,ROW()-1),0,1), C10 + IF(INDEX(Input!$L$7:$L1503,ROW()-1),1,0), 1 ), YEARFRAC( B10 + IF(INDEX(Input!$K$7:$K1503,ROW()-1),0,1), C10 + IF(INDEX(Input!$L$7:$L1503,ROW()-1),1,0), 3 ) ) )} | S10: =IF( E10="", , IF( E10="Simple", L10, (1 + L10 / SWITCH(H10,"Monthly",12,"Quarterly",4,"Semi-annual",2,"Annual",1,1)) ^ SWITCH(H10,"Monthly",12,"Quarterly",4,"Semi-annual",2,"Annual",1,1) - 1 ) ) | T10: {=IF( B10="", , DATEDIF( B10 + IF(INDEX(Input!$K$7:$K1503,ROW()-1),0,1), C10 + IF(INDEX(Input!$L$7:$L1503,ROW()-1),1,0), "Y" ) )} | U10: {=IF( B10="", , (C10 + IF(INDEX(Input!$L$7:$L1503,ROW()-1),1,0)) - EDATE( B10 + IF(INDEX(Input!$K$7:$K1503,ROW()-1),0,1), 12*S10 ) )} | V10: =IF( D10="", , R10*365*366 - 365*D10 ) | W10: =IF( D10="", , D10 - V10 )
I11: 0 | J11: 0 | M11: =IF( E11="", , IF( E11="Simple", L11 * R11, LET( t, R11, m, SWITCH(H11,"Monthly",12,"Quarterly",4,"Semi-annual",2,"Annual",1,1), (1 + L11/m)^(m*t) - 1 ) ) ) | N11: =IF(A11="",,IF(ROW()=2, Input!$C$2 + I11, P10 + I11)) | O11: =IF(A11="",, IF(K11="Initial principal", Input!$C$2 * M11, N11 * M11 ) ) | P11: =IF(A11="",,N11 + O11 + J11) | Q11: =IF(A11="",,IF(ROW()=2,O11,Q10+O11)) | R11: {=IF( B11="", , SWITCH( Input!$C$4, "Actual/365 Fixed", YEARFRAC( B11 + IF(INDEX(Input!$K$7:$K1503,ROW()-1),0,1), C11 + IF(INDEX(Input!$L$7:$L1503,ROW()-1),1,0), 3 ), "Anniversary/365", DATEDIF( B11 + IF(INDEX(Input!$K$7:$K1503,ROW()-1),0,1), C11 + IF(INDEX(Input!$L$7:$L1503,ROW()-1),1,0), "Y" ) + ( (C11 + IF(INDEX(Input!$L$7:$L1503,ROW()-1),1,0)) - EDATE( B11 + IF(INDEX(Input!$K$7:$K1503,ROW()-1),0,1), 12*DATEDIF( B11 + IF(INDEX(Input!$K$7:$K1503,ROW()-1),0,1), C11 + IF(INDEX(Input!$L$7:$L1503,ROW()-1),1,0), "Y" ) ) ) / 365, "Actual/Actual", YEARFRAC( B11 + IF(INDEX(Input!$K$7:$K1503,ROW()-1),0,1), C11 + IF(INDEX(Input!$L$7:$L1503,ROW()-1),1,0), 1 ), YEARFRAC( B11 + IF(INDEX(Input!$K$7:$K1503,ROW()-1),0,1), C11 + IF(INDEX(Input!$L$7:$L1503,ROW()-1),1,0), 3 ) ) )} | S11: =IF( E11="", , IF( E11="Simple", L11, (1 + L11 / SWITCH(H11,"Monthly",12,"Quarterly",4,"Semi-annual",2,"Annual",1,1)) ^ SWITCH(H11,"Monthly",12,"Quarterly",4,"Semi-annual",2,"Annual",1,1) - 1 ) ) | T11: {=IF( B11="", , DATEDIF( B11 + IF(INDEX(Input!$K$7:$K1503,ROW()-1),0,1), C11 + IF(INDEX(Input!$L$7:$L1503,ROW()-1),1,0), "Y" ) )} | U11: {=IF( B11="", , (C11 + IF(INDEX(Input!$L$7:$L1503,ROW()-1),1,0)) - EDATE( B11 + IF(INDEX(Input!$K$7:$K1503,ROW()-1),0,1), 12*S11 ) )} | V11: =IF( D11="", , R11*365*366 - 365*D11 ) | W11: =IF( D11="", , D11 - V11 )
I12: 0 | J12: 0 | M12: =IF( E12="", , IF( E12="Simple", L12 * R12, LET( t, R12, m, SWITCH(H12,"Monthly",12,"Quarterly",4,"Semi-annual",2,"Annual",1,1), (1 + L12/m)^(m*t) - 1 ) ) ) | N12: =IF(A12="",,IF(ROW()=2, Input!$C$2 + I12, P11 + I12)) | O12: =IF(A12="",, IF(K12="Initial principal", Input!$C$2 * M12, N12 * M12 ) ) | P12: =IF(A12="",,N12 + O12 + J12) | Q12: =IF(A12="",,IF(ROW()=2,O12,Q11+O12)) | R12: {=IF( B12="", , SWITCH( Input!$C$4, "Actual/365 Fixed", YEARFRAC( B12 + IF(INDEX(Input!$K$7:$K1503,ROW()-1),0,1), C12 + IF(INDEX(Input!$L$7:$L1503,ROW()-1),1,0), 3 ), "Anniversary/365", DATEDIF( B12 + IF(INDEX(Input!$K$7:$K1503,ROW()-1),0,1), C12 + IF(INDEX(Input!$L$7:$L1503,ROW()-1),1,0), "Y" ) + ( (C12 + IF(INDEX(Input!$L$7:$L1503,ROW()-1),1,0)) - EDATE( B12 + IF(INDEX(Input!$K$7:$K1503,ROW()-1),0,1), 12*DATEDIF( B12 + IF(INDEX(Input!$K$7:$K1503,ROW()-1),0,1), C12 + IF(INDEX(Input!$L$7:$L1503,ROW()-1),1,0), "Y" ) ) ) / 365, "Actual/Actual", YEARFRAC( B12 + IF(INDEX(Input!$K$7:$K1503,ROW()-1),0,1), C12 + IF(INDEX(Input!$L$7:$L1503,ROW()-1),1,0), 1 ), YEARFRAC( B12 + IF(INDEX(Input!$K$7:$K1503,ROW()-1),0,1), C12 + IF(INDEX(Input!$L$7:$L1503,ROW()-1),1,0), 3 ) ) )} | S12: =IF( E12="", , IF( E12="Simple", L12, (1 + L12 / SWITCH(H12,"Monthly",12,"Quarterly",4,"Semi-annual",2,"Annual",1,1)) ^ SWITCH(H12,"Monthly",12,"Quarterly",4,"Semi-annual",2,"Annual",1,1) - 1 ) ) | T12: {=IF( B12="", , DATEDIF( B12 + IF(INDEX(Input!$K$7:$K1503,ROW()-1),0,1), C12 + IF(INDEX(Input!$L$7:$L1503,ROW()-1),1,0), "Y" ) )} | U12: {=IF( B12="", , (C12 + IF(INDEX(Input!$L$7:$L1503,ROW()-1),1,0)) - EDATE( B12 + IF(INDEX(Input!$K$7:$K1503,ROW()-1),0,1), 12*S12 ) )} | V12: =IF( D12="", , R12*365*366 - 365*D12 ) | W12: =IF( D12="", , D12 - V12 )
I13: 0 | J13: 0 | M13: =IF( E13="", , IF( E13="Simple", L13 * R13, LET( t, R13, m, SWITCH(H13,"Monthly",12,"Quarterly",4,"Semi-annual",2,"Annual",1,1), (1 + L13/m)^(m*t) - 1 ) ) ) | N13: =IF(A13="",,IF(ROW()=2, Input!$C$2 + I13, P12 + I13)) | O13: =IF(A13="",, IF(K13="Initial principal", Input!$C$2 * M13, N13 * M13 ) ) | P13: =IF(A13="",,N13 + O13 + J13) | Q13: =IF(A13="",,IF(ROW()=2,O13,Q12+O13)) | R13: {=IF( B13="", , SWITCH( Input!$C$4, "Actual/365 Fixed", YEARFRAC( B13 + IF(INDEX(Input!$K$7:$K1503,ROW()-1),0,1), C13 + IF(INDEX(Input!$L$7:$L1503,ROW()-1),1,0), 3 ), "Anniversary/365", DATEDIF( B13 + IF(INDEX(Input!$K$7:$K1503,ROW()-1),0,1), C13 + IF(INDEX(Input!$L$7:$L1503,ROW()-1),1,0), "Y" ) + ( (C13 + IF(INDEX(Input!$L$7:$L1503,ROW()-1),1,0)) - EDATE( B13 + IF(INDEX(Input!$K$7:$K1503,ROW()-1),0,1), 12*DATEDIF( B13 + IF(INDEX(Input!$K$7:$K1503,ROW()-1),0,1), C13 + IF(INDEX(Input!$L$7:$L1503,ROW()-1),1,0), "Y" ) ) ) / 365, "Actual/Actual", YEARFRAC( B13 + IF(INDEX(Input!$K$7:$K1503,ROW()-1),0,1), C13 + IF(INDEX(Input!$L$7:$L1503,ROW()-1),1,0), 1 ), YEARFRAC( B13 + IF(INDEX(Input!$K$7:$K1503,ROW()-1),0,1), C13 + IF(INDEX(Input!$L$7:$L1503,ROW()-1),1,0), 3 ) ) )} | S13: =IF( E13="", , IF( E13="Simple", L13, (1 + L13 / SWITCH(H13,"Monthly",12,"Quarterly",4,"Semi-annual",2,"Annual",1,1)) ^ SWITCH(H13,"Monthly",12,"Quarterly",4,"Semi-annual",2,"Annual",1,1) - 1 ) ) | T13: {=IF( B13="", , DATEDIF( B13 + IF(INDEX(Input!$K$7:$K1503,ROW()-1),0,1), C13 + IF(INDEX(Input!$L$7:$L1503,ROW()-1),1,0), "Y" ) )} | U13: {=IF( B13="", , (C13 + IF(INDEX(Input!$L$7:$L1503,ROW()-1),1,0)) - EDATE( B13 + IF(INDEX(Input!$K$7:$K1503,ROW()-1),0,1), 12*S13 ) )} | V13: =IF( D13="", , R13*365*366 - 365*D13 ) | W13: =IF( D13="", , D13 - V13 )
I14: 0 | J14: 0 | M14: =IF( E14="", , IF( E14="Simple", L14 * R14, LET( t, R14, m, SWITCH(H14,"Monthly",12,"Quarterly",4,"Semi-annual",2,"Annual",1,1), (1 + L14/m)^(m*t) - 1 ) ) ) | N14: =IF(A14="",,IF(ROW()=2, Input!$C$2 + I14, P13 + I14)) | O14: =IF(A14="",, IF(K14="Initial principal", Input!$C$2 * M14, N14 * M14 ) ) | P14: =IF(A14="",,N14 + O14 + J14) | Q14: =IF(A14="",,IF(ROW()=2,O14,Q13+O14)) | R14: {=IF( B14="", , SWITCH( Input!$C$4, "Actual/365 Fixed", YEARFRAC( B14 + IF(INDEX(Input!$K$7:$K1503,ROW()-1),0,1), C14 + IF(INDEX(Input!$L$7:$L1503,ROW()-1),1,0), 3 ), "Anniversary/365", DATEDIF( B14 + IF(INDEX(Input!$K$7:$K1503,ROW()-1),0,1), C14 + IF(INDEX(Input!$L$7:$L1503,ROW()-1),1,0), "Y" ) + ( (C14 + IF(INDEX(Input!$L$7:$L1503,ROW()-1),1,0)) - EDATE( B14 + IF(INDEX(Input!$K$7:$K1503,ROW()-1),0,1), 12*DATEDIF( B14 + IF(INDEX(Input!$K$7:$K1503,ROW()-1),0,1), C14 + IF(INDEX(Input!$L$7:$L1503,ROW()-1),1,0), "Y" ) ) ) / 365, "Actual/Actual", YEARFRAC( B14 + IF(INDEX(Input!$K$7:$K1503,ROW()-1),0,1), C14 + IF(INDEX(Input!$L$7:$L1503,ROW()-1),1,0), 1 ), YEARFRAC( B14 + IF(INDEX(Input!$K$7:$K1503,ROW()-1),0,1), C14 + IF(INDEX(Input!$L$7:$L1503,ROW()-1),1,0), 3 ) ) )} | S14: =IF( E14="", , IF( E14="Simple", L14, (1 + L14 / SWITCH(H14,"Monthly",12,"Quarterly",4,"Semi-annual",2,"Annual",1,1)) ^ SWITCH(H14,"Monthly",12,"Quarterly",4,"Semi-annual",2,"Annual",1,1) - 1 ) ) | T14: {=IF( B14="", , DATEDIF( B14 + IF(INDEX(Input!$K$7:$K1503,ROW()-1),0,1), C14 + IF(INDEX(Input!$L$7:$L1503,ROW()-1),1,0), "Y" ) )} | U14: {=IF( B14="", , (C14 + IF(INDEX(Input!$L$7:$L1503,ROW()-1),1,0)) - EDATE( B14 + IF(INDEX(Input!$K$7:$K1503,ROW()-1),0,1), 12*S14 ) )} | V14: =IF( D14="", , R14*365*366 - 365*D14 ) | W14: =IF( D14="", , D14 - V14 )
I15: 0 | J15: 0 | M15: =IF( E15="", , IF( E15="Simple", L15 * R15, LET( t, R15, m, SWITCH(H15,"Monthly",12,"Quarterly",4,"Semi-annual",2,"Annual",1,1), (1 + L15/m)^(m*t) - 1 ) ) ) | N15: =IF(A15="",,IF(ROW()=2, Input!$C$2 + I15, P14 + I15)) | O15: =IF(A15="",, IF(K15="Initial principal", Input!$C$2 * M15, N15 * M15 ) ) | P15: =IF(A15="",,N15 + O15 + J15) | Q15: =IF(A15="",,IF(ROW()=2,O15,Q14+O15)) | R15: {=IF( B15="", , SWITCH( Input!$C$4, "Actual/365 Fixed", YEARFRAC( B15 + IF(INDEX(Input!$K$7:$K1503,ROW()-1),0,1), C15 + IF(INDEX(Input!$L$7:$L1503,ROW()-1),1,0), 3 ), "Anniversary/365", DATEDIF( B15 + IF(INDEX(Input!$K$7:$K1503,ROW()-1),0,1), C15 + IF(INDEX(Input!$L$7:$L1503,ROW()-1),1,0), "Y" ) + ( (C15 + IF(INDEX(Input!$L$7:$L1503,ROW()-1),1,0)) - EDATE( B15 + IF(INDEX(Input!$K$7:$K1503,ROW()-1),0,1), 12*DATEDIF( B15 + IF(INDEX(Input!$K$7:$K1503,ROW()-1),0,1), C15 + IF(INDEX(Input!$L$7:$L1503,ROW()-1),1,0), "Y" ) ) ) / 365, "Actual/Actual", YEARFRAC( B15 + IF(INDEX(Input!$K$7:$K1503,ROW()-1),0,1), C15 + IF(INDEX(Input!$L$7:$L1503,ROW()-1),1,0), 1 ), YEARFRAC( B15 + IF(INDEX(Input!$K$7:$K1503,ROW()-1),0,1), C15 + IF(INDEX(Input!$L$7:$L1503,ROW()-1),1,0), 3 ) ) )} | S15: =IF( E15="", , IF( E15="Simple", L15, (1 + L15 / SWITCH(H15,"Monthly",12,"Quarterly",4,"Semi-annual",2,"Annual",1,1)) ^ SWITCH(H15,"Monthly",12,"Quarterly",4,"Semi-annual",2,"Annual",1,1) - 1 ) ) | T15: {=IF( B15="", , DATEDIF( B15 + IF(INDEX(Input!$K$7:$K1503,ROW()-1),0,1), C15 + IF(INDEX(Input!$L$7:$L1503,ROW()-1),1,0), "Y" ) )} | U15: {=IF( B15="", , (C15 + IF(INDEX(Input!$L$7:$L1503,ROW()-1),1,0)) - EDATE( B15 + IF(INDEX(Input!$K$7:$K1503,ROW()-1),0,1), 12*S15 ) )} | V15: =IF( D15="", , R15*365*366 - 365*D15 ) | W15: =IF( D15="", , D15 - V15 )
I16: 0 | J16: 0 | M16: =IF( E16="", , IF( E16="Simple", L16 * R16, LET( t, R16, m, SWITCH(H16,"Monthly",12,"Quarterly",4,"Semi-annual",2,"Annual",1,1), (1 + L16/m)^(m*t) - 1 ) ) ) | N16: =IF(A16="",,IF(ROW()=2, Input!$C$2 + I16, P15 + I16)) | O16: =IF(A16="",, IF(K16="Initial principal", Input!$C$2 * M16, N16 * M16 ) ) | P16: =IF(A16="",,N16 + O16 + J16) | Q16: =IF(A16="",,IF(ROW()=2,O16,Q15+O16)) | R16: {=IF( B16="", , SWITCH( Input!$C$4, "Actual/365 Fixed", YEARFRAC( B16 + IF(INDEX(Input!$K$7:$K1503,ROW()-1),0,1), C16 + IF(INDEX(Input!$L$7:$L1503,ROW()-1),1,0), 3 ), "Anniversary/365", DATEDIF( B16 + IF(INDEX(Input!$K$7:$K1503,ROW()-1),0,1), C16 + IF(INDEX(Input!$L$7:$L1503,ROW()-1),1,0), "Y" ) + ( (C16 + IF(INDEX(Input!$L$7:$L1503,ROW()-1),1,0)) - EDATE( B16 + IF(INDEX(Input!$K$7:$K1503,ROW()-1),0,1), 12*DATEDIF( B16 + IF(INDEX(Input!$K$7:$K1503,ROW()-1),0,1), C16 + IF(INDEX(Input!$L$7:$L1503,ROW()-1),1,0), "Y" ) ) ) / 365, "Actual/Actual", YEARFRAC( B16 + IF(INDEX(Input!$K$7:$K1503,ROW()-1),0,1), C16 + IF(INDEX(Input!$L$7:$L1503,ROW()-1),1,0), 1 ), YEARFRAC( B16 + IF(INDEX(Input!$K$7:$K1503,ROW()-1),0,1), C16 + IF(INDEX(Input!$L$7:$L1503,ROW()-1),1,0), 3 ) ) )} | S16: =IF( E16="", , IF( E16="Simple", L16, (1 + L16 / SWITCH(H16,"Monthly",12,"Quarterly",4,"Semi-annual",2,"Annual",1,1)) ^ SWITCH(H16,"Monthly",12,"Quarterly",4,"Semi-annual",2,"Annual",1,1) - 1 ) ) | T16: {=IF( B16="", , DATEDIF( B16 + IF(INDEX(Input!$K$7:$K1503,ROW()-1),0,1), C16 + IF(INDEX(Input!$L$7:$L1503,ROW()-1),1,0), "Y" ) )} | U16: {=IF( B16="", , (C16 + IF(INDEX(Input!$L$7:$L1503,ROW()-1),1,0)) - EDATE( B16 + IF(INDEX(Input!$K$7:$K1503,ROW()-1),0,1), 12*S16 ) )} | V16: =IF( D16="", , R16*365*366 - 365*D16 ) | W16: =IF( D16="", , D16 - V16 )
I17: 0 | J17: 0 | M17: =IF( E17="", , IF( E17="Simple", L17 * R17, LET( t, R17, m, SWITCH(H17,"Monthly",12,"Quarterly",4,"Semi-annual",2,"Annual",1,1), (1 + L17/m)^(m*t) - 1 ) ) ) | N17: =IF(A17="",,IF(ROW()=2, Input!$C$2 + I17, P16 + I17)) | O17: =IF(A17="",, IF(K17="Initial principal", Input!$C$2 * M17, N17 * M17 ) ) | P17: =IF(A17="",,N17 + O17 + J17) | Q17: =IF(A17="",,IF(ROW()=2,O17,Q16+O17)) | R17: {=IF( B17="", , SWITCH( Input!$C$4, "Actual/365 Fixed", YEARFRAC( B17 + IF(INDEX(Input!$K$7:$K1503,ROW()-1),0,1), C17 + IF(INDEX(Input!$L$7:$L1503,ROW()-1),1,0), 3 ), "Anniversary/365", DATEDIF( B17 + IF(INDEX(Input!$K$7:$K1503,ROW()-1),0,1), C17 + IF(INDEX(Input!$L$7:$L1503,ROW()-1),1,0), "Y" ) + ( (C17 + IF(INDEX(Input!$L$7:$L1503,ROW()-1),1,0)) - EDATE( B17 + IF(INDEX(Input!$K$7:$K1503,ROW()-1),0,1), 12*DATEDIF( B17 + IF(INDEX(Input!$K$7:$K1503,ROW()-1),0,1), C17 + IF(INDEX(Input!$L$7:$L1503,ROW()-1),1,0), "Y" ) ) ) / 365, "Actual/Actual", YEARFRAC( B17 + IF(INDEX(Input!$K$7:$K1503,ROW()-1),0,1), C17 + IF(INDEX(Input!$L$7:$L1503,ROW()-1),1,0), 1 ), YEARFRAC( B17 + IF(INDEX(Input!$K$7:$K1503,ROW()-1),0,1), C17 + IF(INDEX(Input!$L$7:$L1503,ROW()-1),1,0), 3 ) ) )} | S17: =IF( E17="", , IF( E17="Simple", L17, (1 + L17 / SWITCH(H17,"Monthly",12,"Quarterly",4,"Semi-annual",2,"Annual",1,1)) ^ SWITCH(H17,"Monthly",12,"Quarterly",4,"Semi-annual",2,"Annual",1,1) - 1 ) ) | T17: {=IF( B17="", , DATEDIF( B17 + IF(INDEX(Input!$K$7:$K1503,ROW()-1),0,1), C17 + IF(INDEX(Input!$L$7:$L1503,ROW()-1),1,0), "Y" ) )} | U17: {=IF( B17="", , (C17 + IF(INDEX(Input!$L$7:$L1503,ROW()-1),1,0)) - EDATE( B17 + IF(INDEX(Input!$K$7:$K1503,ROW()-1),0,1), 12*S17 ) )} | V17: =IF( D17="", , R17*365*366 - 365*D17 ) | W17: =IF( D17="", , D17 - V17 )
I18: 0 | J18: 0 | M18: =IF( E18="", , IF( E18="Simple", L18 * R18, LET( t, R18, m, SWITCH(H18,"Monthly",12,"Quarterly",4,"Semi-annual",2,"Annual",1,1), (1 + L18/m)^(m*t) - 1 ) ) ) | N18: =IF(A18="",,IF(ROW()=2, Input!$C$2 + I18, P17 + I18)) | O18: =IF(A18="",, IF(K18="Initial principal", Input!$C$2 * M18, N18 * M18 ) ) | P18: =IF(A18="",,N18 + O18 + J18) | Q18: =IF(A18="",,IF(ROW()=2,O18,Q17+O18)) | R18: {=IF( B18="", , SWITCH( Input!$C$4, "Actual/365 Fixed", YEARFRAC( B18 + IF(INDEX(Input!$K$7:$K1503,ROW()-1),0,1), C18 + IF(INDEX(Input!$L$7:$L1503,ROW()-1),1,0), 3 ), "Anniversary/365", DATEDIF( B18 + IF(INDEX(Input!$K$7:$K1503,ROW()-1),0,1), C18 + IF(INDEX(Input!$L$7:$L1503,ROW()-1),1,0), "Y" ) + ( (C18 + IF(INDEX(Input!$L$7:$L1503,ROW()-1),1,0)) - EDATE( B18 + IF(INDEX(Input!$K$7:$K1503,ROW()-1),0,1), 12*DATEDIF( B18 + IF(INDEX(Input!$K$7:$K1503,ROW()-1),0,1), C18 + IF(INDEX(Input!$L$7:$L1503,ROW()-1),1,0), "Y" ) ) ) / 365, "Actual/Actual", YEARFRAC( B18 + IF(INDEX(Input!$K$7:$K1503,ROW()-1),0,1), C18 + IF(INDEX(Input!$L$7:$L1503,ROW()-1),1,0), 1 ), YEARFRAC( B18 + IF(INDEX(Input!$K$7:$K1503,ROW()-1),0,1), C18 + IF(INDEX(Input!$L$7:$L1503,ROW()-1),1,0), 3 ) ) )} | S18: =IF( E18="", , IF( E18="Simple", L18, (1 + L18 / SWITCH(H18,"Monthly",12,"Quarterly",4,"Semi-annual",2,"Annual",1,1)) ^ SWITCH(H18,"Monthly",12,"Quarterly",4,"Semi-annual",2,"Annual",1,1) - 1 ) ) | T18: {=IF( B18="", , DATEDIF( B18 + IF(INDEX(Input!$K$7:$K1503,ROW()-1),0,1), C18 + IF(INDEX(Input!$L$7:$L1503,ROW()-1),1,0), "Y" ) )} | U18: {=IF( B18="", , (C18 + IF(INDEX(Input!$L$7:$L1503,ROW()-1),1,0)) - EDATE( B18 + IF(INDEX(Input!$K$7:$K1503,ROW()-1),0,1), 12*S18 ) )} | V18: =IF( D18="", , R18*365*366 - 365*D18 ) | W18: =IF( D18="", , D18 - V18 )
I19: 0 | J19: 0 | M19: =IF( E19="", , IF( E19="Simple", L19 * R19, LET( t, R19, m, SWITCH(H19,"Monthly",12,"Quarterly",4,"Semi-annual",2,"Annual",1,1), (1 + L19/m)^(m*t) - 1 ) ) ) | N19: =IF(A19="",,IF(ROW()=2, Input!$C$2 + I19, P18 + I19)) | O19: =IF(A19="",, IF(K19="Initial principal", Input!$C$2 * M19, N19 * M19 ) ) | P19: =IF(A19="",,N19 + O19 + J19) | Q19: =IF(A19="",,IF(ROW()=2,O19,Q18+O19)) | R19: {=IF( B19="", , SWITCH( Input!$C$4, "Actual/365 Fixed", YEARFRAC( B19 + IF(INDEX(Input!$K$7:$K1503,ROW()-1),0,1), C19 + IF(INDEX(Input!$L$7:$L1503,ROW()-1),1,0), 3 ), "Anniversary/365", DATEDIF( B19 + IF(INDEX(Input!$K$7:$K1503,ROW()-1),0,1), C19 + IF(INDEX(Input!$L$7:$L1503,ROW()-1),1,0), "Y" ) + ( (C19 + IF(INDEX(Input!$L$7:$L1503,ROW()-1),1,0)) - EDATE( B19 + IF(INDEX(Input!$K$7:$K1503,ROW()-1),0,1), 12*DATEDIF( B19 + IF(INDEX(Input!$K$7:$K1503,ROW()-1),0,1), C19 + IF(INDEX(Input!$L$7:$L1503,ROW()-1),1,0), "Y" ) ) ) / 365, "Actual/Actual", YEARFRAC( B19 + IF(INDEX(Input!$K$7:$K1503,ROW()-1),0,1), C19 + IF(INDEX(Input!$L$7:$L1503,ROW()-1),1,0), 1 ), YEARFRAC( B19 + IF(INDEX(Input!$K$7:$K1503,ROW()-1),0,1), C19 + IF(INDEX(Input!$L$7:$L1503,ROW()-1),1,0), 3 ) ) )} | S19: =IF( E19="", , IF( E19="Simple", L19, (1 + L19 / SWITCH(H19,"Monthly",12,"Quarterly",4,"Semi-annual",2,"Annual",1,1)) ^ SWITCH(H19,"Monthly",12,"Quarterly",4,"Semi-annual",2,"Annual",1,1) - 1 ) ) | T19: {=IF( B19="", , DATEDIF( B19 + IF(INDEX(Input!$K$7:$K1503,ROW()-1),0,1), C19 + IF(INDEX(Input!$L$7:$L1503,ROW()-1),1,0), "Y" ) )} | U19: {=IF( B19="", , (C19 + IF(INDEX(Input!$L$7:$L1503,ROW()-1),1,0)) - EDATE( B19 + IF(INDEX(Input!$K$7:$K1503,ROW()-1),0,1), 12*S19 ) )} | V19: =IF( D19="", , R19*365*366 - 365*D19 ) | W19: =IF( D19="", , D19 - V19 )
I20: 0 | J20: 0 | M20: =IF( E20="", , IF( E20="Simple", L20 * R20, LET( t, R20, m, SWITCH(H20,"Monthly",12,"Quarterly",4,"Semi-annual",2,"Annual",1,1), (1 + L20/m)^(m*t) - 1 ) ) ) | N20: =IF(A20="",,IF(ROW()=2, Input!$C$2 + I20, P19 + I20)) | O20: =IF(A20="",, IF(K20="Initial principal", Input!$C$2 * M20, N20 * M20 ) ) | P20: =IF(A20="",,N20 + O20 + J20) | Q20: =IF(A20="",,IF(ROW()=2,O20,Q19+O20)) | R20: {=IF( B20="", , SWITCH( Input!$C$4, "Actual/365 Fixed", YEARFRAC( B20 + IF(INDEX(Input!$K$7:$K1503,ROW()-1),0,1), C20 + IF(INDEX(Input!$L$7:$L1503,ROW()-1),1,0), 3 ), "Anniversary/365", DATEDIF( B20 + IF(INDEX(Input!$K$7:$K1503,ROW()-1),0,1), C20 + IF(INDEX(Input!$L$7:$L1503,ROW()-1),1,0), "Y" ) + ( (C20 + IF(INDEX(Input!$L$7:$L1503,ROW()-1),1,0)) - EDATE( B20 + IF(INDEX(Input!$K$7:$K1503,ROW()-1),0,1), 12*DATEDIF( B20 + IF(INDEX(Input!$K$7:$K1503,ROW()-1),0,1), C20 + IF(INDEX(Input!$L$7:$L1503,ROW()-1),1,0), "Y" ) ) ) / 365, "Actual/Actual", YEARFRAC( B20 + IF(INDEX(Input!$K$7:$K1503,ROW()-1),0,1), C20 + IF(INDEX(Input!$L$7:$L1503,ROW()-1),1,0), 1 ), YEARFRAC( B20 + IF(INDEX(Input!$K$7:$K1503,ROW()-1),0,1), C20 + IF(INDEX(Input!$L$7:$L1503,ROW()-1),1,0), 3 ) ) )} | S20: =IF( E20="", , IF( E20="Simple", L20, (1 + L20 / SWITCH(H20,"Monthly",12,"Quarterly",4,"Semi-annual",2,"Annual",1,1)) ^ SWITCH(H20,"Monthly",12,"Quarterly",4,"Semi-annual",2,"Annual",1,1) - 1 ) ) | T20: {=IF( B20="", , DATEDIF( B20 + IF(INDEX(Input!$K$7:$K1503,ROW()-1),0,1), C20 + IF(INDEX(Input!$L$7:$L1503,ROW()-1),1,0), "Y" ) )} | U20: {=IF( B20="", , (C20 + IF(INDEX(Input!$L$7:$L1503,ROW()-1),1,0)) - EDATE( B20 + IF(INDEX(Input!$K$7:$K1503,ROW()-1),0,1), 12*S20 ) )} | V20: =IF( D20="", , R20*365*366 - 365*D20 ) | W20: =IF( D20="", , D20 - V20 )
I21: 0 | J21: 0 | M21: =IF( E21="", , IF( E21="Simple", L21 * R21, LET( t, R21, m, SWITCH(H21,"Monthly",12,"Quarterly",4,"Semi-annual",2,"Annual",1,1), (1 + L21/m)^(m*t) - 1 ) ) ) | N21: =IF(A21="",,IF(ROW()=2, Input!$C$2 + I21, P20 + I21)) | O21: =IF(A21="",, IF(K21="Initial principal", Input!$C$2 * M21, N21 * M21 ) ) | P21: =IF(A21="",,N21 + O21 + J21) | Q21: =IF(A21="",,IF(ROW()=2,O21,Q20+O21)) | R21: {=IF( B21="", , SWITCH( Input!$C$4, "Actual/365 Fixed", YEARFRAC( B21 + IF(INDEX(Input!$K$7:$K1503,ROW()-1),0,1), C21 + IF(INDEX(Input!$L$7:$L1503,ROW()-1),1,0), 3 ), "Anniversary/365", DATEDIF( B21 + IF(INDEX(Input!$K$7:$K1503,ROW()-1),0,1), C21 + IF(INDEX(Input!$L$7:$L1503,ROW()-1),1,0), "Y" ) + ( (C21 + IF(INDEX(Input!$L$7:$L1503,ROW()-1),1,0)) - EDATE( B21 + IF(INDEX(Input!$K$7:$K1503,ROW()-1),0,1), 12*DATEDIF( B21 + IF(INDEX(Input!$K$7:$K1503,ROW()-1),0,1), C21 + IF(INDEX(Input!$L$7:$L1503,ROW()-1),1,0), "Y" ) ) ) / 365, "Actual/Actual", YEARFRAC( B21 + IF(INDEX(Input!$K$7:$K1503,ROW()-1),0,1), C21 + IF(INDEX(Input!$L$7:$L1503,ROW()-1),1,0), 1 ), YEARFRAC( B21 + IF(INDEX(Input!$K$7:$K1503,ROW()-1),0,1), C21 + IF(INDEX(Input!$L$7:$L1503,ROW()-1),1,0), 3 ) ) )} | S21: =IF( E21="", , IF( E21="Simple", L21, (1 + L21 / SWITCH(H21,"Monthly",12,"Quarterly",4,"Semi-annual",2,"Annual",1,1)) ^ SWITCH(H21,"Monthly",12,"Quarterly",4,"Semi-annual",2,"Annual",1,1) - 1 ) ) | T21: {=IF( B21="", , DATEDIF( B21 + IF(INDEX(Input!$K$7:$K1503,ROW()-1),0,1), C21 + IF(INDEX(Input!$L$7:$L1503,ROW()-1),1,0), "Y" ) )} | U21: {=IF( B21="", , (C21 + IF(INDEX(Input!$L$7:$L1503,ROW()-1),1,0)) - EDATE( B21 + IF(INDEX(Input!$K$7:$K1503,ROW()-1),0,1), 12*S21 ) )} | V21: =IF( D21="", , R21*365*366 - 365*D21 ) | W21: =IF( D21="", , D21 - V21 )
I22: 0 | J22: 0 | M22: =IF( E22="", , IF( E22="Simple", L22 * R22, LET( t, R22, m, SWITCH(H22,"Monthly",12,"Quarterly",4,"Semi-annual",2,"Annual",1,1), (1 + L22/m)^(m*t) - 1 ) ) ) | N22: =IF(A22="",,IF(ROW()=2, Input!$C$2 + I22, P21 + I22)) | O22: =IF(A22="",, IF(K22="Initial principal", Input!$C$2 * M22, N22 * M22 ) ) | P22: =IF(A22="",,N22 + O22 + J22) | Q22: =IF(A22="",,IF(ROW()=2,O22,Q21+O22)) | R22: {=IF( B22="", , SWITCH( Input!$C$4, "Actual/365 Fixed", YEARFRAC( B22 + IF(INDEX(Input!$K$7:$K1503,ROW()-1),0,1), C22 + IF(INDEX(Input!$L$7:$L1503,ROW()-1),1,0), 3 ), "Anniversary/365", DATEDIF( B22 + IF(INDEX(Input!$K$7:$K1503,ROW()-1),0,1), C22 + IF(INDEX(Input!$L$7:$L1503,ROW()-1),1,0), "Y" ) + ( (C22 + IF(INDEX(Input!$L$7:$L1503,ROW()-1),1,0)) - EDATE( B22 + IF(INDEX(Input!$K$7:$K1503,ROW()-1),0,1), 12*DATEDIF( B22 + IF(INDEX(Input!$K$7:$K1503,ROW()-1),0,1), C22 + IF(INDEX(Input!$L$7:$L1503,ROW()-1),1,0), "Y" ) ) ) / 365, "Actual/Actual", YEARFRAC( B22 + IF(INDEX(Input!$K$7:$K1503,ROW()-1),0,1), C22 + IF(INDEX(Input!$L$7:$L1503,ROW()-1),1,0), 1 ), YEARFRAC( B22 + IF(INDEX(Input!$K$7:$K1503,ROW()-1),0,1), C22 + IF(INDEX(Input!$L$7:$L1503,ROW()-1),1,0), 3 ) ) )} | S22: =IF( E22="", , IF( E22="Simple", L22, (1 + L22 / SWITCH(H22,"Monthly",12,"Quarterly",4,"Semi-annual",2,"Annual",1,1)) ^ SWITCH(H22,"Monthly",12,"Quarterly",4,"Semi-annual",2,"Annual",1,1) - 1 ) ) | T22: {=IF( B22="", , DATEDIF( B22 + IF(INDEX(Input!$K$7:$K1503,ROW()-1),0,1), C22 + IF(INDEX(Input!$L$7:$L1503,ROW()-1),1,0), "Y" ) )} | U22: {=IF( B22="", , (C22 + IF(INDEX(Input!$L$7:$L1503,ROW()-1),1,0)) - EDATE( B22 + IF(INDEX(Input!$K$7:$K1503,ROW()-1),0,1), 12*S22 ) )} | V22: =IF( D22="", , R22*365*366 - 365*D22 ) | W22: =IF( D22="", , D22 - V22 )
I23: 0 | J23: 0 | M23: =IF( E23="", , IF( E23="Simple", L23 * R23, LET( t, R23, m, SWITCH(H23,"Monthly",12,"Quarterly",4,"Semi-annual",2,"Annual",1,1), (1 + L23/m)^(m*t) - 1 ) ) ) | N23: =IF(A23="",,IF(ROW()=2, Input!$C$2 + I23, P22 + I23)) | O23: =IF(A23="",, IF(K23="Initial principal", Input!$C$2 * M23, N23 * M23 ) ) | P23: =IF(A23="",,N23 + O23 + J23) | Q23: =IF(A23="",,IF(ROW()=2,O23,Q22+O23)) | R23: {=IF( B23="", , SWITCH( Input!$C$4, "Actual/365 Fixed", YEARFRAC( B23 + IF(INDEX(Input!$K$7:$K1503,ROW()-1),0,1), C23 + IF(INDEX(Input!$L$7:$L1503,ROW()-1),1,0), 3 ), "Anniversary/365", DATEDIF( B23 + IF(INDEX(Input!$K$7:$K1503,ROW()-1),0,1), C23 + IF(INDEX(Input!$L$7:$L1503,ROW()-1),1,0), "Y" ) + ( (C23 + IF(INDEX(Input!$L$7:$L1503,ROW()-1),1,0)) - EDATE( B23 + IF(INDEX(Input!$K$7:$K1503,ROW()-1),0,1), 12*DATEDIF( B23 + IF(INDEX(Input!$K$7:$K1503,ROW()-1),0,1), C23 + IF(INDEX(Input!$L$7:$L1503,ROW()-1),1,0), "Y" ) ) ) / 365, "Actual/Actual", YEARFRAC( B23 + IF(INDEX(Input!$K$7:$K1503,ROW()-1),0,1), C23 + IF(INDEX(Input!$L$7:$L1503,ROW()-1),1,0), 1 ), YEARFRAC( B23 + IF(INDEX(Input!$K$7:$K1503,ROW()-1),0,1), C23 + IF(INDEX(Input!$L$7:$L1503,ROW()-1),1,0), 3 ) ) )} | S23: =IF( E23="", , IF( E23="Simple", L23, (1 + L23 / SWITCH(H23,"Monthly",12,"Quarterly",4,"Semi-annual",2,"Annual",1,1)) ^ SWITCH(H23,"Monthly",12,"Quarterly",4,"Semi-annual",2,"Annual",1,1) - 1 ) ) | T23: {=IF( B23="", , DATEDIF( B23 + IF(INDEX(Input!$K$7:$K1503,ROW()-1),0,1), C23 + IF(INDEX(Input!$L$7:$L1503,ROW()-1),1,0), "Y" ) )} | U23: {=IF( B23="", , (C23 + IF(INDEX(Input!$L$7:$L1503,ROW()-1),1,0)) - EDATE( B23 + IF(INDEX(Input!$K$7:$K1503,ROW()-1),0,1), 12*S23 ) )} | V23: =IF( D23="", , R23*365*366 - 365*D23 ) | W23: =IF( D23="", , D23 - V23 )
I24: 0 | J24: 0 | M24: =IF( E24="", , IF( E24="Simple", L24 * R24, LET( t, R24, m, SWITCH(H24,"Monthly",12,"Quarterly",4,"Semi-annual",2,"Annual",1,1), (1 + L24/m)^(m*t) - 1 ) ) ) | N24: =IF(A24="",,IF(ROW()=2, Input!$C$2 + I24, P23 + I24)) | O24: =IF(A24="",, IF(K24="Initial principal", Input!$C$2 * M24, N24 * M24 ) ) | P24: =IF(A24="",,N24 + O24 + J24) | Q24: =IF(A24="",,IF(ROW()=2,O24,Q23+O24)) | R24: {=IF( B24="", , SWITCH( Input!$C$4, "Actual/365 Fixed", YEARFRAC( B24 + IF(INDEX(Input!$K$7:$K1503,ROW()-1),0,1), C24 + IF(INDEX(Input!$L$7:$L1503,ROW()-1),1,0), 3 ), "Anniversary/365", DATEDIF( B24 + IF(INDEX(Input!$K$7:$K1503,ROW()-1),0,1), C24 + IF(INDEX(Input!$L$7:$L1503,ROW()-1),1,0), "Y" ) + ( (C24 + IF(INDEX(Input!$L$7:$L1503,ROW()-1),1,0)) - EDATE( B24 + IF(INDEX(Input!$K$7:$K1503,ROW()-1),0,1), 12*DATEDIF( B24 + IF(INDEX(Input!$K$7:$K1503,ROW()-1),0,1), C24 + IF(INDEX(Input!$L$7:$L1503,ROW()-1),1,0), "Y" ) ) ) / 365, "Actual/Actual", YEARFRAC( B24 + IF(INDEX(Input!$K$7:$K1503,ROW()-1),0,1), C24 + IF(INDEX(Input!$L$7:$L1503,ROW()-1),1,0), 1 ), YEARFRAC( B24 + IF(INDEX(Input!$K$7:$K1503,ROW()-1),0,1), C24 + IF(INDEX(Input!$L$7:$L1503,ROW()-1),1,0), 3 ) ) )} | S24: =IF( E24="", , IF( E24="Simple", L24, (1 + L24 / SWITCH(H24,"Monthly",12,"Quarterly",4,"Semi-annual",2,"Annual",1,1)) ^ SWITCH(H24,"Monthly",12,"Quarterly",4,"Semi-annual",2,"Annual",1,1) - 1 ) ) | T24: {=IF( B24="", , DATEDIF( B24 + IF(INDEX(Input!$K$7:$K1503,ROW()-1),0,1), C24 + IF(INDEX(Input!$L$7:$L1503,ROW()-1),1,0), "Y" ) )} | U24: {=IF( B24="", , (C24 + IF(INDEX(Input!$L$7:$L1503,ROW()-1),1,0)) - EDATE( B24 + IF(INDEX(Input!$K$7:$K1503,ROW()-1),0,1), 12*S24 ) )} | V24: =IF( D24="", , R24*365*366 - 365*D24 ) | W24: =IF( D24="", , D24 - V24 )
I25: 0 | J25: 0 | M25: =IF( E25="", , IF( E25="Simple", L25 * R25, LET( t, R25, m, SWITCH(H25,"Monthly",12,"Quarterly",4,"Semi-annual",2,"Annual",1,1), (1 + L25/m)^(m*t) - 1 ) ) ) | N25: =IF(A25="",,IF(ROW()=2, Input!$C$2 + I25, P24 + I25)) | O25: =IF(A25="",, IF(K25="Initial principal", Input!$C$2 * M25, N25 * M25 ) ) | P25: =IF(A25="",,N25 + O25 + J25) | Q25: =IF(A25="",,IF(ROW()=2,O25,Q24+O25)) | R25: {=IF( B25="", , SWITCH( Input!$C$4, "Actual/365 Fixed", YEARFRAC( B25 + IF(INDEX(Input!$K$7:$K1503,ROW()-1),0,1), C25 + IF(INDEX(Input!$L$7:$L1503,ROW()-1),1,0), 3 ), "Anniversary/365", DATEDIF( B25 + IF(INDEX(Input!$K$7:$K1503,ROW()-1),0,1), C25 + IF(INDEX(Input!$L$7:$L1503,ROW()-1),1,0), "Y" ) + ( (C25 + IF(INDEX(Input!$L$7:$L1503,ROW()-1),1,0)) - EDATE( B25 + IF(INDEX(Input!$K$7:$K1503,ROW()-1),0,1), 12*DATEDIF( B25 + IF(INDEX(Input!$K$7:$K1503,ROW()-1),0,1), C25 + IF(INDEX(Input!$L$7:$L1503,ROW()-1),1,0), "Y" ) ) ) / 365, "Actual/Actual", YEARFRAC( B25 + IF(INDEX(Input!$K$7:$K1503,ROW()-1),0,1), C25 + IF(INDEX(Input!$L$7:$L1503,ROW()-1),1,0), 1 ), YEARFRAC( B25 + IF(INDEX(Input!$K$7:$K1503,ROW()-1),0,1), C25 + IF(INDEX(Input!$L$7:$L1503,ROW()-1),1,0), 3 ) ) )} | S25: =IF( E25="", , IF( E25="Simple", L25, (1 + L25 / SWITCH(H25,"Monthly",12,"Quarterly",4,"Semi-annual",2,"Annual",1,1)) ^ SWITCH(H25,"Monthly",12,"Quarterly",4,"Semi-annual",2,"Annual",1,1) - 1 ) ) | T25: {=IF( B25="", , DATEDIF( B25 + IF(INDEX(Input!$K$7:$K1503,ROW()-1),0,1), C25 + IF(INDEX(Input!$L$7:$L1503,ROW()-1),1,0), "Y" ) )} | U25: {=IF( B25="", , (C25 + IF(INDEX(Input!$L$7:$L1503,ROW()-1),1,0)) - EDATE( B25 + IF(INDEX(Input!$K$7:$K1503,ROW()-1),0,1), 12*S25 ) )} | V25: =IF( D25="", , R25*365*366 - 365*D25 ) | W25: =IF( D25="", , D25 - V25 )
I26: 0 | J26: 0 | M26: =IF( E26="", , IF( E26="Simple", L26 * R26, LET( t, R26, m, SWITCH(H26,"Monthly",12,"Quarterly",4,"Semi-annual",2,"Annual",1,1), (1 + L26/m)^(m*t) - 1 ) ) ) | N26: =IF(A26="",,IF(ROW()=2, Input!$C$2 + I26, P25 + I26)) | O26: =IF(A26="",, IF(K26="Initial principal", Input!$C$2 * M26, N26 * M26 ) ) | P26: =IF(A26="",,N26 + O26 + J26) | Q26: =IF(A26="",,IF(ROW()=2,O26,Q25+O26)) | R26: {=IF( B26="", , SWITCH( Input!$C$4, "Actual/365 Fixed", YEARFRAC( B26 + IF(INDEX(Input!$K$7:$K1503,ROW()-1),0,1), C26 + IF(INDEX(Input!$L$7:$L1503,ROW()-1),1,0), 3 ), "Anniversary/365", DATEDIF( B26 + IF(INDEX(Input!$K$7:$K1503,ROW()-1),0,1), C26 + IF(INDEX(Input!$L$7:$L1503,ROW()-1),1,0), "Y" ) + ( (C26 + IF(INDEX(Input!$L$7:$L1503,ROW()-1),1,0)) - EDATE( B26 + IF(INDEX(Input!$K$7:$K1503,ROW()-1),0,1), 12*DATEDIF( B26 + IF(INDEX(Input!$K$7:$K1503,ROW()-1),0,1), C26 + IF(INDEX(Input!$L$7:$L1503,ROW()-1),1,0), "Y" ) ) ) / 365, "Actual/Actual", YEARFRAC( B26 + IF(INDEX(Input!$K$7:$K1503,ROW()-1),0,1), C26 + IF(INDEX(Input!$L$7:$L1503,ROW()-1),1,0), 1 ), YEARFRAC( B26 + IF(INDEX(Input!$K$7:$K1503,ROW()-1),0,1), C26 + IF(INDEX(Input!$L$7:$L1503,ROW()-1),1,0), 3 ) ) )} | S26: =IF( E26="", , IF( E26="Simple", L26, (1 + L26 / SWITCH(H26,"Monthly",12,"Quarterly",4,"Semi-annual",2,"Annual",1,1)) ^ SWITCH(H26,"Monthly",12,"Quarterly",4,"Semi-annual",2,"Annual",1,1) - 1 ) ) | T26: {=IF( B26="", , DATEDIF( B26 + IF(INDEX(Input!$K$7:$K1503,ROW()-1),0,1), C26 + IF(INDEX(Input!$L$7:$L1503,ROW()-1),1,0), "Y" ) )} | U26: {=IF( B26="", , (C26 + IF(INDEX(Input!$L$7:$L1503,ROW()-1),1,0)) - EDATE( B26 + IF(INDEX(Input!$K$7:$K1503,ROW()-1),0,1), 12*S26 ) )} | V26: =IF( D26="", , R26*365*366 - 365*D26 ) | W26: =IF( D26="", , D26 - V26 )
I27: 0 | J27: 0 | M27: =IF( E27="", , IF( E27="Simple", L27 * R27, LET( t, R27, m, SWITCH(H27,"Monthly",12,"Quarterly",4,"Semi-annual",2,"Annual",1,1), (1 + L27/m)^(m*t) - 1 ) ) ) | N27: =IF(A27="",,IF(ROW()=2, Input!$C$2 + I27, P26 + I27)) | O27: =IF(A27="",, IF(K27="Initial principal", Input!$C$2 * M27, N27 * M27 ) ) | P27: =IF(A27="",,N27 + O27 + J27) | Q27: =IF(A27="",,IF(ROW()=2,O27,Q26+O27)) | R27: {=IF( B27="", , SWITCH( Input!$C$4, "Actual/365 Fixed", YEARFRAC( B27 + IF(INDEX(Input!$K$7:$K1503,ROW()-1),0,1), C27 + IF(INDEX(Input!$L$7:$L1503,ROW()-1),1,0), 3 ), "Anniversary/365", DATEDIF( B27 + IF(INDEX(Input!$K$7:$K1503,ROW()-1),0,1), C27 + IF(INDEX(Input!$L$7:$L1503,ROW()-1),1,0), "Y" ) + ( (C27 + IF(INDEX(Input!$L$7:$L1503,ROW()-1),1,0)) - EDATE( B27 + IF(INDEX(Input!$K$7:$K1503,ROW()-1),0,1), 12*DATEDIF( B27 + IF(INDEX(Input!$K$7:$K1503,ROW()-1),0,1), C27 + IF(INDEX(Input!$L$7:$L1503,ROW()-1),1,0), "Y" ) ) ) / 365, "Actual/Actual", YEARFRAC( B27 + IF(INDEX(Input!$K$7:$K1503,ROW()-1),0,1), C27 + IF(INDEX(Input!$L$7:$L1503,ROW()-1),1,0), 1 ), YEARFRAC( B27 + IF(INDEX(Input!$K$7:$K1503,ROW()-1),0,1), C27 + IF(INDEX(Input!$L$7:$L1503,ROW()-1),1,0), 3 ) ) )} | S27: =IF( E27="", , IF( E27="Simple", L27, (1 + L27 / SWITCH(H27,"Monthly",12,"Quarterly",4,"Semi-annual",2,"Annual",1,1)) ^ SWITCH(H27,"Monthly",12,"Quarterly",4,"Semi-annual",2,"Annual",1,1) - 1 ) ) | T27: {=IF( B27="", , DATEDIF( B27 + IF(INDEX(Input!$K$7:$K1503,ROW()-1),0,1), C27 + IF(INDEX(Input!$L$7:$L1503,ROW()-1),1,0), "Y" ) )} | U27: {=IF( B27="", , (C27 + IF(INDEX(Input!$L$7:$L1503,ROW()-1),1,0)) - EDATE( B27 + IF(INDEX(Input!$K$7:$K1503,ROW()-1),0,1), 12*S27 ) )} | V27: =IF( D27="", , R27*365*366 - 365*D27 ) | W27: =IF( D27="", , D27 - V27 )
I28: 0 | J28: 0 | M28: =IF( E28="", , IF( E28="Simple", L28 * R28, LET( t, R28, m, SWITCH(H28,"Monthly",12,"Quarterly",4,"Semi-annual",2,"Annual",1,1), (1 + L28/m)^(m*t) - 1 ) ) ) | N28: =IF(A28="",,IF(ROW()=2, Input!$C$2 + I28, P27 + I28)) | O28: =IF(A28="",, IF(K28="Initial principal", Input!$C$2 * M28, N28 * M28 ) ) | P28: =IF(A28="",,N28 + O28 + J28) | Q28: =IF(A28="",,IF(ROW()=2,O28,Q27+O28)) | R28: {=IF( B28="", , SWITCH( Input!$C$4, "Actual/365 Fixed", YEARFRAC( B28 + IF(INDEX(Input!$K$7:$K1503,ROW()-1),0,1), C28 + IF(INDEX(Input!$L$7:$L1503,ROW()-1),1,0), 3 ), "Anniversary/365", DATEDIF( B28 + IF(INDEX(Input!$K$7:$K1503,ROW()-1),0,1), C28 + IF(INDEX(Input!$L$7:$L1503,ROW()-1),1,0), "Y" ) + ( (C28 + IF(INDEX(Input!$L$7:$L1503,ROW()-1),1,0)) - EDATE( B28 + IF(INDEX(Input!$K$7:$K1503,ROW()-1),0,1), 12*DATEDIF( B28 + IF(INDEX(Input!$K$7:$K1503,ROW()-1),0,1), C28 + IF(INDEX(Input!$L$7:$L1503,ROW()-1),1,0), "Y" ) ) ) / 365, "Actual/Actual", YEARFRAC( B28 + IF(INDEX(Input!$K$7:$K1503,ROW()-1),0,1), C28 + IF(INDEX(Input!$L$7:$L1503,ROW()-1),1,0), 1 ), YEARFRAC( B28 + IF(INDEX(Input!$K$7:$K1503,ROW()-1),0,1), C28 + IF(INDEX(Input!$L$7:$L1503,ROW()-1),1,0), 3 ) ) )} | S28: =IF( E28="", , IF( E28="Simple", L28, (1 + L28 / SWITCH(H28,"Monthly",12,"Quarterly",4,"Semi-annual",2,"Annual",1,1)) ^ SWITCH(H28,"Monthly",12,"Quarterly",4,"Semi-annual",2,"Annual",1,1) - 1 ) ) | T28: {=IF( B28="", , DATEDIF( B28 + IF(INDEX(Input!$K$7:$K1503,ROW()-1),0,1), C28 + IF(INDEX(Input!$L$7:$L1503,ROW()-1),1,0), "Y" ) )} | U28: {=IF( B28="", , (C28 + IF(INDEX(Input!$L$7:$L1503,ROW()-1),1,0)) - EDATE( B28 + IF(INDEX(Input!$K$7:$K1503,ROW()-1),0,1), 12*S28 ) )} | V28: =IF( D28="", , R28*365*366 - 365*D28 ) | W28: =IF( D28="", , D28 - V28 )
